2022-05-12 17:58:29,239 ERROR: Exception on /favicon.ico [GET][in C:\Users\mikie\PycharmProjects\BearPills\venv\lib\site-packages\flask\app.py:1457]
Traceback (most recent call last):
  File "C:\Users\mikie\PycharmProjects\BearPills\venv\lib\site-packages\sqlalchemy\engine\base.py", line 1808, in _execute_context
    self.dialect.do_execute(
  File "C:\Users\mikie\PycharmProjects\BearPills\venv\lib\site-packages\sqlalchemy\engine\default.py", line 732, in do_execute
    cursor.execute(statement, parameters)
sqlite3.OperationalError: no such table: user

The above exception was the direct cause of the following exception:

Traceback (most recent call last):
  File "C:\Users\mikie\PycharmProjects\BearPills\venv\lib\site-packages\flask\app.py", line 2073, in wsgi_app
    response = self.full_dispatch_request()
  File "C:\Users\mikie\PycharmProjects\BearPills\venv\lib\site-packages\flask\app.py", line 1518, in full_dispatch_request
    rv = self.handle_user_exception(e)
  File "C:\Users\mikie\PycharmProjects\BearPills\venv\lib\site-packages\flask\app.py", line 1514, in full_dispatch_request
    rv = self.preprocess_request()
  File "C:\Users\mikie\PycharmProjects\BearPills\venv\lib\site-packages\flask\app.py", line 1857, in preprocess_request
    rv = self.ensure_sync(before_func)()
  File "C:\Users\mikie\PycharmProjects\BearPills\app\home\routes.py", line 13, in search_navbar
    if current_user.is_authenticated:
  File "C:\Users\mikie\PycharmProjects\BearPills\venv\lib\site-packages\werkzeug\local.py", line 436, in __get__
    obj = instance._get_current_object()
  File "C:\Users\mikie\PycharmProjects\BearPills\venv\lib\site-packages\werkzeug\local.py", line 565, in _get_current_object
    return self.__local()  # type: ignore
  File "C:\Users\mikie\PycharmProjects\BearPills\venv\lib\site-packages\flask_login\utils.py", line 26, in <lambda>
    current_user = LocalProxy(lambda: _get_user())
  File "C:\Users\mikie\PycharmProjects\BearPills\venv\lib\site-packages\flask_login\utils.py", line 346, in _get_user
    current_app.login_manager._load_user()
  File "C:\Users\mikie\PycharmProjects\BearPills\venv\lib\site-packages\flask_login\login_manager.py", line 318, in _load_user
    user = self._user_callback(user_id)
  File "C:\Users\mikie\PycharmProjects\BearPills\app\models.py", line 11, in load_user
    return User.query.get(int(id))
  File "<string>", line 2, in get
  File "C:\Users\mikie\PycharmProjects\BearPills\venv\lib\site-packages\sqlalchemy\util\deprecations.py", line 401, in warned
    return fn(*args, **kwargs)
  File "C:\Users\mikie\PycharmProjects\BearPills\venv\lib\site-packages\sqlalchemy\orm\query.py", line 943, in get
    return self._get_impl(ident, loading.load_on_pk_identity)
  File "C:\Users\mikie\PycharmProjects\BearPills\venv\lib\site-packages\sqlalchemy\orm\query.py", line 947, in _get_impl
    return self.session._get_impl(
  File "C:\Users\mikie\PycharmProjects\BearPills\venv\lib\site-packages\sqlalchemy\orm\session.py", line 2892, in _get_impl
    return db_load_fn(
  File "C:\Users\mikie\PycharmProjects\BearPills\venv\lib\site-packages\sqlalchemy\orm\loading.py", line 530, in load_on_pk_identity
    session.execute(
  File "C:\Users\mikie\PycharmProjects\BearPills\venv\lib\site-packages\sqlalchemy\orm\session.py", line 1692, in execute
    result = conn._execute_20(statement, params or {}, execution_options)
  File "C:\Users\mikie\PycharmProjects\BearPills\venv\lib\site-packages\sqlalchemy\engine\base.py", line 1620, in _execute_20
    return meth(self, args_10style, kwargs_10style, execution_options)
  File "C:\Users\mikie\PycharmProjects\BearPills\venv\lib\site-packages\sqlalchemy\sql\elements.py", line 325, in _execute_on_connection
    return connection._execute_clauseelement(
  File "C:\Users\mikie\PycharmProjects\BearPills\venv\lib\site-packages\sqlalchemy\engine\base.py", line 1487, in _execute_clauseelement
    ret = self._execute_context(
  File "C:\Users\mikie\PycharmProjects\BearPills\venv\lib\site-packages\sqlalchemy\engine\base.py", line 1851, in _execute_context
    self._handle_dbapi_exception(
  File "C:\Users\mikie\PycharmProjects\BearPills\venv\lib\site-packages\sqlalchemy\engine\base.py", line 2032, in _handle_dbapi_exception
    util.raise_(
  File "C:\Users\mikie\PycharmProjects\BearPills\venv\lib\site-packages\sqlalchemy\util\compat.py", line 207, in raise_
    raise exception
  File "C:\Users\mikie\PycharmProjects\BearPills\venv\lib\site-packages\sqlalchemy\engine\base.py", line 1808, in _execute_context
    self.dialect.do_execute(
  File "C:\Users\mikie\PycharmProjects\BearPills\venv\lib\site-packages\sqlalchemy\engine\default.py", line 732, in do_execute
    cursor.execute(statement, parameters)
sqlalchemy.exc.OperationalError: (sqlite3.OperationalError) no such table: user
[SQL: SELECT user.id AS user_id, user.username AS user_username, user.email_address AS user_email_address, user.password_hash AS user_password_hash 
FROM user 
WHERE user.id = ?]
[parameters: (1,)]
(Background on this error at: https://sqlalche.me/e/14/e3q8)
2022-05-12 18:01:23,472 INFO: BearPills Startup[in C:\Users\mikie\PycharmProjects\BearPills\app\__init__.py:93]
